<?xml version="1.0" encoding="utf-8"?>
<!-- This URDF was automatically created by SolidWorks to URDF Exporter! Originally created by Stephen Brawner (brawner@gmail.com)
     Commit Version: 1.5.1-0-g916b5db  Build Version: 1.5.7152.31018
     For more information, please see http://wiki.ros.org/sw_urdf_exporter -->
<robot name="vss_robot">
  <link name="base_link">
    <inertial>
      <origin xyz="0 -6.93889390390723E-18 0.0300217633588078" rpy="0 0 0" />
      <mass value="0.113374359717356" />
      <inertia ixx="7.53748708949032E-05" ixy="1.00192251695485E-21" ixz="-2.05369079266837E-21" iyy="7.94977991899896E-05" iyz="4.67673387095597E-21" izz="8.66719183047349E-05" />
    </inertial>
    <visual>
      <origin xyz="0 0 0" rpy="0 0 0" />
      <geometry>
        <mesh filename="package://simulation_vsss/meshes/base_link.stl" />
      </geometry>
      <material name="">
        <color rgba="0.698039215686274 0.698039215686274 0.698039215686274 1" />
      </material>
    </visual>
    <collision>
      <origin xyz="0 0 0" rpy="0 0 0" />
      <geometry>
        <mesh filename="package://simulation_vsss/meshes/base_link_collision.stl" />
      </geometry>
    </collision>
  </link>
  <link name="top_link">
    <inertial>
      <origin xyz="0 -1.3878E-17 0.061" rpy="0 0 0" />
      <mass value="0.012087" />
      <inertia ixx="6.2903E-06" ixy="2.3039E-22" ixz="-2.9084E-23" iyy="5.6698E-06" iyz="-3.7247E-24" izz="1.1952E-05" />
    </inertial>
    <visual>
      <origin xyz="0 0 61e-3" rpy="0 0 0" />
      <geometry>
        <box size="75e-3 75e-3 2e-3"/>
      </geometry>
      <material name="">
        <color rgba="1 1 1 1" />
      </material>
    </visual>
    <collision>
      <origin xyz="0 0 61e-3" rpy="0 0 0" />
      <geometry>
        <box size="75e-3 75e-3 2e-3"/>
      </geometry>
    </collision>
  </link>
  <joint name="top_joint" type="fixed">
    <origin xyz="0 0 0" rpy="0 0 0" />
    <parent link="base_link" />
    <child link="top_link" />
    <axis xyz="0 0 0" />
  </joint>
  <!-- <link name="lateral_right_link">
    <inertial>
      <origin xyz="6.9389E-18 -0.0385 0.03" rpy="0 0 0" />
      <mass value="0.00918" />
      <inertia ixx="2.7571E-06" ixy="-2.5312E-23" ixz="0" iyy="7.0571E-06" iyz="0" izz="4.3062E-06" />
    </inertial>
    <visual>
      <origin xyz="0 -38.5e-3 30e-3" rpy="0 0 0" />
      <geometry>
        <box size="75e-3 2e-3 60e-3"/>
      </geometry>
      <material name="">
        <color rgba="1 1 1 1" />
      </material>
    </visual>
  </link>
  <joint name="lateral_right_joint" type="fixed">
    <origin xyz="0 0 0" rpy="0 0 0" />
    <parent link="base_link" />
    <child link="lateral_right_link" />
    <axis xyz="0 0 0" />
  </joint>
  <link name="lateral_left_link">
    <inertial>
      <origin xyz="0 0.0385 0.03" rpy="0 0 0" />
      <mass value="0.00918" />
      <inertia ixx="2.7571E-06" ixy="-8.7658E-24" ixz="-2.1599E-22" iyy="7.0571E-06" iyz="3.112E-24" izz="4.3062E-06" />
    </inertial>
    <visual>
      <origin xyz="0 38.5e-3 30e-3" rpy="0 0 0" />
      <geometry>
        <box size="75e-3 2e-3 60e-3"/>
      </geometry>
      <material name="">
        <color rgba="1 1 1 1" />
      </material>
    </visual>
  </link>
  <joint name="lateral_left_joint" type="fixed">
    <origin xyz="0 0 0" rpy="0 0 0" />
    <parent link="base_link" />
    <child link="lateral_left_link" />
    <axis xyz="0 0 0" />
  </joint> -->
  <link name="wheel_right_link">
    <inertial>
      <origin xyz="0 0.004 3.4694E-18" rpy="0 0 0" />
      <mass value="0.018064" />
      <inertia ixx="2.9189E-06" ixy="-3.4908E-39" ixz="2.1559E-38" iyy="5.645E-06" iyz="-1.0274E-38" izz="2.9189E-06" />
    </inertial>
    <visual>
      <origin xyz="0 4e-3 0" rpy="1.5707963 0 0" />
      <geometry>
        <cylinder radius="25e-3" length="8e-3"/>
      </geometry>
      <material name="">
        <color rgba="0.79608 0.82353 0.93725 1" />
      </material>
    </visual>
    <collision>
      <origin xyz="0 4e-3 0" rpy="1.5707963 0 0" />
      <geometry>
        <cylinder radius="25e-3" length="8e-3"/>
      </geometry>
    </collision>
  </link>
  <joint name="wheel_right_joint" type="continuous">
    <origin xyz="0 -0.0355 0.023" rpy="0 0 0" />
    <parent link="base_link" />
    <child link="wheel_right_link" />
    <axis xyz="0 1 0" />
    <limit effort="73e-3" velocity="68" />
    <dynamics damping="0.0023" friction="0.01" />
  </joint>
  <link name="wheel_left_link">
    <inertial>
      <origin xyz="0 -0.004 0" rpy="0 0 0" />
      <mass value="0.018064" />
      <inertia ixx="2.9189E-06" ixy="-3.4908E-39" ixz="2.1559E-38" iyy="5.645E-06" iyz="-1.0274E-38" izz="2.9189E-06" />
    </inertial>
    <visual>
      <origin xyz="0 -4e-3 0" rpy="1.5707963 0 0" />
      <geometry>
        <cylinder radius="25e-3" length="8e-3"/>
      </geometry>
      <material name="">
        <color rgba="0.79608 0.82353 0.93725 1" />
      </material>
    </visual>
    <collision>
      <origin xyz="0 -4e-3 0" rpy="1.5707963 0 0" />
      <geometry>
        <cylinder radius="25e-3" length="8e-3"/>
      </geometry>
    </collision>
  </link>
  <joint name="wheel_left_joint" type="continuous">
    <origin xyz="0 0.0355 0.023" rpy="0 0 0" />
    <parent link="base_link" />
    <child link="wheel_left_link" />
    <axis xyz="0 1 0" />
    <limit effort="73e-3" velocity="68" />
    <dynamics damping="0.0023" friction="0.01" />
  </joint>
</robot>
